Activating virtual environment:  SNPNet
/faststorage/project/NLPPred/snp-compression/SNPNet/bin/python
compressing chromosomes
loading model
Loading data
Traceback (most recent call last):
  File "/faststorage/project/NLPPred/snp-compression/SNPNet/lib/python3.8/site-packages/fsspec/mapping.py", line 135, in __getitem__
    result = self.fs.cat(k)
  File "/faststorage/project/NLPPred/snp-compression/SNPNet/lib/python3.8/site-packages/fsspec/spec.py", line 739, in cat
    return self.cat_file(paths[0], **kwargs)
  File "/faststorage/project/NLPPred/snp-compression/SNPNet/lib/python3.8/site-packages/fsspec/spec.py", line 649, in cat_file
    with self.open(path, "rb", **kwargs) as f:
  File "/faststorage/project/NLPPred/snp-compression/SNPNet/lib/python3.8/site-packages/fsspec/spec.py", line 1009, in open
    f = self._open(
  File "/faststorage/project/NLPPred/snp-compression/SNPNet/lib/python3.8/site-packages/fsspec/implementations/local.py", line 155, in _open
    return LocalFileOpener(path, mode, fs=self, **kwargs)
  File "/faststorage/project/NLPPred/snp-compression/SNPNet/lib/python3.8/site-packages/fsspec/implementations/local.py", line 250, in __init__
    self._open()
  File "/faststorage/project/NLPPred/snp-compression/SNPNet/lib/python3.8/site-packages/fsspec/implementations/local.py", line 255, in _open
    self.f = open(self.path, mode=self.mode)
FileNotFoundError: [Errno 2] No such file or directory: '/faststorage/project/NLPPred/snp-compression/src/data/../../data/interim/chrom_src/apply/../../data/interim/genotype.zarr/.zarray'

During handling of the above exception, another exception occurred:

Traceback (most recent call last):
  File "/faststorage/project/NLPPred/snp-compression/SNPNet/lib/python3.8/site-packages/zarr/core.py", line 206, in _load_metadata_nosync
    meta_bytes = self._store[mkey]
  File "/faststorage/project/NLPPred/snp-compression/SNPNet/lib/python3.8/site-packages/zarr/storage.py", line 546, in __getitem__
    return self._mutable_mapping[key]
  File "/faststorage/project/NLPPred/snp-compression/SNPNet/lib/python3.8/site-packages/fsspec/mapping.py", line 139, in __getitem__
    raise KeyError(key)
KeyError: '.zarray'

During handling of the above exception, another exception occurred:

Traceback (most recent call last):
  File "src/apply/validate.py", line 95, in <module>
    ds, val, test = load_dataset(path, chrom)
  File "./src/data/dataloaders.py", line 298, in load_dataset
    arr = da.from_zarr(path)
  File "/faststorage/project/NLPPred/snp-compression/SNPNet/lib/python3.8/site-packages/dask/array/core.py", line 3384, in from_zarr
    z = zarr.Array(mapper, read_only=True, path=component, **kwargs)
  File "/faststorage/project/NLPPred/snp-compression/SNPNet/lib/python3.8/site-packages/zarr/core.py", line 180, in __init__
    self._load_metadata()
  File "/faststorage/project/NLPPred/snp-compression/SNPNet/lib/python3.8/site-packages/zarr/core.py", line 197, in _load_metadata
    self._load_metadata_nosync()
  File "/faststorage/project/NLPPred/snp-compression/SNPNet/lib/python3.8/site-packages/zarr/core.py", line 208, in _load_metadata_nosync
    raise ArrayNotFoundError(self._path)
zarr.errors.ArrayNotFoundError: array not found at path %r' ''
